Traceback (most recent call last):
  File "C:\Users\Fujitsu\AppData\Local\Programs\Python\Python312\Lib\site-packages\jupyter_core\utils\__init__.py", line 154, in wrapped
    asyncio.get_running_loop()
RuntimeError: no running event loop

During handling of the above exception, another exception occurred:

Traceback (most recent call last):
  File "C:\Users\Fujitsu\AppData\Local\Programs\Python\Python312\Lib\site-packages\jupyter_cache\executors\utils.py", line 58, in single_nb_execution
    executenb(
  File "C:\Users\Fujitsu\AppData\Local\Programs\Python\Python312\Lib\site-packages\nbclient\client.py", line 1319, in execute
    return NotebookClient(nb=nb, resources=resources, km=km, **kwargs).execute()
           ^^^^^^^^^^^^^^^^^^^^^^^^^^^^^^^^^^^^^^^^^^^^^^^^^^^^^^^^^^^^^^^^^^^^^
  File "C:\Users\Fujitsu\AppData\Local\Programs\Python\Python312\Lib\site-packages\jupyter_core\utils\__init__.py", line 158, in wrapped
    return loop.run_until_complete(inner)
           ^^^^^^^^^^^^^^^^^^^^^^^^^^^^^^
  File "C:\Users\Fujitsu\AppData\Local\Programs\Python\Python312\Lib\asyncio\base_events.py", line 687, in run_until_complete
    return future.result()
           ^^^^^^^^^^^^^^^
  File "C:\Users\Fujitsu\AppData\Local\Programs\Python\Python312\Lib\site-packages\nbclient\client.py", line 709, in async_execute
    await self.async_execute_cell(
  File "C:\Users\Fujitsu\AppData\Local\Programs\Python\Python312\Lib\site-packages\nbclient\client.py", line 1062, in async_execute_cell
    await self._check_raise_for_error(cell, cell_index, exec_reply)
  File "C:\Users\Fujitsu\AppData\Local\Programs\Python\Python312\Lib\site-packages\nbclient\client.py", line 918, in _check_raise_for_error
    raise CellExecutionError.from_cell_and_msg(cell, exec_reply_content)
nbclient.exceptions.CellExecutionError: An error occurred while executing the following cell:
------------------
import pandas as pd
from sklearn.ensemble import RandomForestRegressor
from sklearn.pipeline import make_pipeline

from sktime.forecasting.compose import make_reduction
from sktime.split import temporal_train_test_split
from sktime.transformations.series.date import DateTimeFeatures

pd.options.mode.chained_assignment = None
pd.set_option("display.max_columns", None)

# %%
# Load M5 Data and prepare
y = pd.read_pickle("global_fc/y.pkl")
X = pd.read_pickle("global_fc/X.pkl")
------------------


[31m---------------------------------------------------------------------------[39m
[31mFileNotFoundError[39m                         Traceback (most recent call last)
[36mCell[39m[36m [39m[32mIn[21][39m[32m, line 14[39m
[32m     10[39m pd.set_option([33m"[39m[33mdisplay.max_columns[39m[33m"[39m, [38;5;28;01mNone[39;00m)
[32m     12[39m [38;5;66;03m# %%[39;00m
[32m     13[39m [38;5;66;03m# Load M5 Data and prepare[39;00m
[32m---> [39m[32m14[39m y = [43mpd[49m[43m.[49m[43mread_pickle[49m[43m([49m[33;43m"[39;49m[33;43mglobal_fc/y.pkl[39;49m[33;43m"[39;49m[43m)[49m
[32m     15[39m X = pd.read_pickle([33m"[39m[33mglobal_fc/X.pkl[39m[33m"[39m)

[36mFile [39m[32m~\AppData\Local\Programs\Python\Python312\Lib\site-packages\pandas\io\pickle.py:189[39m, in [36mread_pickle[39m[34m(filepath_or_buffer, compression, storage_options)[39m
[32m    125[39m [38;5;250m[39m[33;03m"""[39;00m
[32m    126[39m [33;03mLoad pickled pandas object (or any object) from file.[39;00m
[32m    127[39m 
[32m   (...)[39m[32m    186[39m [33;03m4    4    9[39;00m
[32m    187[39m [33;03m"""[39;00m
[32m    188[39m excs_to_catch = ([38;5;167;01mAttributeError[39;00m, [38;5;167;01mImportError[39;00m, [38;5;167;01mModuleNotFoundError[39;00m, [38;5;167;01mTypeError[39;00m)
[32m--> [39m[32m189[39m [38;5;28;01mwith[39;00m [43mget_handle[49m[43m([49m
[32m    190[39m [43m    [49m[43mfilepath_or_buffer[49m[43m,[49m
[32m    191[39m [43m    [49m[33;43m"[39;49m[33;43mrb[39;49m[33;43m"[39;49m[43m,[49m
[32m    192[39m [43m    [49m[43mcompression[49m[43m=[49m[43mcompression[49m[43m,[49m
[32m    193[39m [43m    [49m[43mis_text[49m[43m=[49m[38;5;28;43;01mFalse[39;49;00m[43m,[49m
[32m    194[39m [43m    [49m[43mstorage_options[49m[43m=[49m[43mstorage_options[49m[43m,[49m
[32m    195[39m [43m[49m[43m)[49m [38;5;28;01mas[39;00m handles:
[32m    196[39m     [38;5;66;03m# 1) try standard library Pickle[39;00m
[32m    197[39m     [38;5;66;03m# 2) try pickle_compat (older pandas version) to handle subclass changes[39;00m
[32m    198[39m     [38;5;66;03m# 3) try pickle_compat with latin-1 encoding upon a UnicodeDecodeError[39;00m
[32m    200[39m     [38;5;28;01mtry[39;00m:
[32m    201[39m         [38;5;66;03m# TypeError for Cython complaints about object.__new__ vs Tick.__new__[39;00m
[32m    202[39m         [38;5;28;01mtry[39;00m:

[36mFile [39m[32m~\AppData\Local\Programs\Python\Python312\Lib\site-packages\pandas\io\common.py:872[39m, in [36mget_handle[39m[34m(path_or_buf, mode, encoding, compression, memory_map, is_text, errors, storage_options)[39m
[32m    863[39m         handle = [38;5;28mopen[39m(
[32m    864[39m             handle,
[32m    865[39m             ioargs.mode,
[32m   (...)[39m[32m    868[39m             newline=[33m"[39m[33m"[39m,
[32m    869[39m         )
[32m    870[39m     [38;5;28;01melse[39;00m:
[32m    871[39m         [38;5;66;03m# Binary mode[39;00m
[32m--> [39m[32m872[39m         handle = [38;5;28;43mopen[39;49m[43m([49m[43mhandle[49m[43m,[49m[43m [49m[43mioargs[49m[43m.[49m[43mmode[49m[43m)[49m
[32m    873[39m     handles.append(handle)
[32m    875[39m [38;5;66;03m# Convert BytesIO or file objects passed with an encoding[39;00m

[31mFileNotFoundError[39m: [Errno 2] No such file or directory: 'global_fc/y.pkl'

