Traceback (most recent call last):
  File "C:\Users\Fujitsu\AppData\Local\Programs\Python\Python312\Lib\site-packages\jupyter_core\utils\__init__.py", line 154, in wrapped
    asyncio.get_running_loop()
RuntimeError: no running event loop

During handling of the above exception, another exception occurred:

Traceback (most recent call last):
  File "C:\Users\Fujitsu\AppData\Local\Programs\Python\Python312\Lib\site-packages\jupyter_cache\executors\utils.py", line 58, in single_nb_execution
    executenb(
  File "C:\Users\Fujitsu\AppData\Local\Programs\Python\Python312\Lib\site-packages\nbclient\client.py", line 1319, in execute
    return NotebookClient(nb=nb, resources=resources, km=km, **kwargs).execute()
           ^^^^^^^^^^^^^^^^^^^^^^^^^^^^^^^^^^^^^^^^^^^^^^^^^^^^^^^^^^^^^^^^^^^^^
  File "C:\Users\Fujitsu\AppData\Local\Programs\Python\Python312\Lib\site-packages\jupyter_core\utils\__init__.py", line 158, in wrapped
    return loop.run_until_complete(inner)
           ^^^^^^^^^^^^^^^^^^^^^^^^^^^^^^
  File "C:\Users\Fujitsu\AppData\Local\Programs\Python\Python312\Lib\asyncio\base_events.py", line 687, in run_until_complete
    return future.result()
           ^^^^^^^^^^^^^^^
  File "C:\Users\Fujitsu\AppData\Local\Programs\Python\Python312\Lib\site-packages\nbclient\client.py", line 709, in async_execute
    await self.async_execute_cell(
  File "C:\Users\Fujitsu\AppData\Local\Programs\Python\Python312\Lib\site-packages\nbclient\client.py", line 1062, in async_execute_cell
    await self._check_raise_for_error(cell, cell_index, exec_reply)
  File "C:\Users\Fujitsu\AppData\Local\Programs\Python\Python312\Lib\site-packages\nbclient\client.py", line 918, in _check_raise_for_error
    raise CellExecutionError.from_cell_and_msg(cell, exec_reply_content)
nbclient.exceptions.CellExecutionError: An error occurred while executing the following cell:
------------------
network = InceptionTimeClassifier(n_epochs=75, verbose=False)
network.fit(X_train, y_train)
network.score(X_test, y_test)
------------------


[31m---------------------------------------------------------------------------[39m
[31mModuleNotFoundError[39m                       Traceback (most recent call last)
[36mFile [39m[32m~\AppData\Local\Programs\Python\Python312\Lib\site-packages\sktime\utils\validation\_dependencies.py:240[39m, in [36m_check_dl_dependencies[39m[34m(msg, severity)[39m
[32m    239[39m [38;5;28;01mtry[39;00m:
[32m--> [39m[32m240[39m     [43mimport_module[49m[43m([49m[33;43m"[39;49m[33;43mtensorflow[39;49m[33;43m"[39;49m[43m)[49m
[32m    241[39m     [38;5;28;01mreturn[39;00m [38;5;28;01mTrue[39;00m

[36mFile [39m[32m~\AppData\Local\Programs\Python\Python312\Lib\importlib\__init__.py:90[39m, in [36mimport_module[39m[34m(name, package)[39m
[32m     89[39m         level += [32m1[39m
[32m---> [39m[32m90[39m [38;5;28;01mreturn[39;00m [43m_bootstrap[49m[43m.[49m[43m_gcd_import[49m[43m([49m[43mname[49m[43m[[49m[43mlevel[49m[43m:[49m[43m][49m[43m,[49m[43m [49m[43mpackage[49m[43m,[49m[43m [49m[43mlevel[49m[43m)[49m

[36mFile [39m[32m<frozen importlib._bootstrap>:1387[39m, in [36m_gcd_import[39m[34m(name, package, level)[39m

[36mFile [39m[32m<frozen importlib._bootstrap>:1360[39m, in [36m_find_and_load[39m[34m(name, import_)[39m

[36mFile [39m[32m<frozen importlib._bootstrap>:1324[39m, in [36m_find_and_load_unlocked[39m[34m(name, import_)[39m

[31mModuleNotFoundError[39m: No module named 'tensorflow'

The above exception was the direct cause of the following exception:

[31mModuleNotFoundError[39m                       Traceback (most recent call last)
[36mCell[39m[36m [39m[32mIn[4][39m[32m, line 1[39m
[32m----> [39m[32m1[39m network = [43mInceptionTimeClassifier[49m[43m([49m[43mn_epochs[49m[43m=[49m[32;43m75[39;49m[43m,[49m[43m [49m[43mverbose[49m[43m=[49m[38;5;28;43;01mFalse[39;49;00m[43m)[49m
[32m      2[39m network.fit(X_train, y_train)
[32m      3[39m network.score(X_test, y_test)

[36mFile [39m[32m~\AppData\Local\Programs\Python\Python312\Lib\site-packages\sktime\classification\deep_learning\inceptiontime.py:70[39m, in [36mInceptionTimeClassifier.__init__[39m[34m(self, n_epochs, batch_size, kernel_size, n_filters, use_residual, use_bottleneck, bottleneck_size, depth, callbacks, random_state, verbose, loss, metrics)[39m
[32m     54[39m [38;5;28;01mdef[39;00m[38;5;250m [39m[34m__init__[39m(
[32m     55[39m     [38;5;28mself[39m,
[32m     56[39m     n_epochs=[32m1500[39m,
[32m   (...)[39m[32m     68[39m     metrics=[38;5;28;01mNone[39;00m,
[32m     69[39m ):
[32m---> [39m[32m70[39m     [43m_check_dl_dependencies[49m[43m([49m[43mseverity[49m[43m=[49m[33;43m"[39;49m[33;43merror[39;49m[33;43m"[39;49m[43m)[49m
[32m     71[39m     [38;5;28msuper[39m().[34m__init__[39m()
[32m     73[39m     [38;5;28mself[39m.verbose = verbose

[36mFile [39m[32m~\AppData\Local\Programs\Python\Python312\Lib\site-packages\sktime\utils\validation\_dependencies.py:244[39m, in [36m_check_dl_dependencies[39m[34m(msg, severity)[39m
[32m    242[39m [38;5;28;01mexcept[39;00m [38;5;167;01mModuleNotFoundError[39;00m [38;5;28;01mas[39;00m e:
[32m    243[39m     [38;5;28;01mif[39;00m severity == [33m"[39m[33merror[39m[33m"[39m:
[32m--> [39m[32m244[39m         [38;5;28;01mraise[39;00m [38;5;167;01mModuleNotFoundError[39;00m(msg) [38;5;28;01mfrom[39;00m[38;5;250m [39m[34;01me[39;00m
[32m    245[39m     [38;5;28;01melif[39;00m severity == [33m"[39m[33mwarning[39m[33m"[39m:
[32m    246[39m         warnings.warn(msg, stacklevel=[32m2[39m)

[31mModuleNotFoundError[39m: tensorflow is required for deep learning functionality in `sktime`. To install these dependencies, run: `pip install sktime[dl]`

