Traceback (most recent call last):
  File "C:\Users\Fujitsu\AppData\Local\Programs\Python\Python312\Lib\site-packages\jupyter_core\utils\__init__.py", line 154, in wrapped
    asyncio.get_running_loop()
RuntimeError: no running event loop

During handling of the above exception, another exception occurred:

Traceback (most recent call last):
  File "C:\Users\Fujitsu\AppData\Local\Programs\Python\Python312\Lib\site-packages\jupyter_cache\executors\utils.py", line 58, in single_nb_execution
    executenb(
  File "C:\Users\Fujitsu\AppData\Local\Programs\Python\Python312\Lib\site-packages\nbclient\client.py", line 1319, in execute
    return NotebookClient(nb=nb, resources=resources, km=km, **kwargs).execute()
           ^^^^^^^^^^^^^^^^^^^^^^^^^^^^^^^^^^^^^^^^^^^^^^^^^^^^^^^^^^^^^^^^^^^^^
  File "C:\Users\Fujitsu\AppData\Local\Programs\Python\Python312\Lib\site-packages\jupyter_core\utils\__init__.py", line 158, in wrapped
    return loop.run_until_complete(inner)
           ^^^^^^^^^^^^^^^^^^^^^^^^^^^^^^
  File "C:\Users\Fujitsu\AppData\Local\Programs\Python\Python312\Lib\asyncio\base_events.py", line 687, in run_until_complete
    return future.result()
           ^^^^^^^^^^^^^^^
  File "C:\Users\Fujitsu\AppData\Local\Programs\Python\Python312\Lib\site-packages\nbclient\client.py", line 709, in async_execute
    await self.async_execute_cell(
  File "C:\Users\Fujitsu\AppData\Local\Programs\Python\Python312\Lib\site-packages\nbclient\client.py", line 1062, in async_execute_cell
    await self._check_raise_for_error(cell, cell_index, exec_reply)
  File "C:\Users\Fujitsu\AppData\Local\Programs\Python\Python312\Lib\site-packages\nbclient\client.py", line 918, in _check_raise_for_error
    raise CellExecutionError.from_cell_and_msg(cell, exec_reply_content)
nbclient.exceptions.CellExecutionError: An error occurred while executing the following cell:
------------------
import sys

sys.path.insert(0, "..")

import pandas as pd
import seaborn as sns

sns.set_theme()
sns.set_color_codes()

from sktime.annotation.clasp import ClaSPSegmentation, find_dominant_window_sizes
from sktime.annotation.plotting.utils import (
    plot_time_series_with_change_points,
    plot_time_series_with_profiles,
)
from sktime.datasets import load_electric_devices_segmentation
------------------


[31m---------------------------------------------------------------------------[39m
[31mImportError[39m                               Traceback (most recent call last)
[36mCell[39m[36m [39m[32mIn[1][39m[32m, line 5[39m
[32m      1[39m [38;5;28;01mimport[39;00m[38;5;250m [39m[34;01msys[39;00m
[32m      3[39m sys.path.insert([32m0[39m, [33m"[39m[33m..[39m[33m"[39m)
[32m----> [39m[32m5[39m [38;5;28;01mimport[39;00m[38;5;250m [39m[34;01mpandas[39;00m[38;5;250m [39m[38;5;28;01mas[39;00m[38;5;250m [39m[34;01mpd[39;00m
[32m      6[39m [38;5;28;01mimport[39;00m[38;5;250m [39m[34;01mseaborn[39;00m[38;5;250m [39m[38;5;28;01mas[39;00m[38;5;250m [39m[34;01msns[39;00m
[32m      8[39m sns.set_theme()

[36mFile [39m[32mD:\masterprog\XAMPP\htdocs\PSD\tugas1-proyek-datasains\.venv\Lib\site-packages\examples\..\pandas\__init__.py:29[39m
[32m     26[39m         _missing_dependencies.append([33mf[39m[33m"[39m[38;5;132;01m{[39;00m_dependency[38;5;132;01m}[39;00m[33m: [39m[38;5;132;01m{[39;00m_e[38;5;132;01m}[39;00m[33m"[39m)
[32m     28[39m [38;5;28;01mif[39;00m _missing_dependencies:  [38;5;66;03m# pragma: no cover[39;00m
[32m---> [39m[32m29[39m     [38;5;28;01mraise[39;00m [38;5;167;01mImportError[39;00m(
[32m     30[39m         [33m"[39m[33mUnable to import required dependencies:[39m[38;5;130;01m\n[39;00m[33m"[39m + [33m"[39m[38;5;130;01m\n[39;00m[33m"[39m.join(_missing_dependencies)
[32m     31[39m     )
[32m     32[39m [38;5;28;01mdel[39;00m _hard_dependencies, _dependency, _missing_dependencies
[32m     34[39m [38;5;28;01mtry[39;00m:
[32m     35[39m     [38;5;66;03m# numpy compat[39;00m

[31mImportError[39m: Unable to import required dependencies:
numpy: Error importing numpy: you should not try to import numpy from
        its source directory; please exit the numpy source tree, and relaunch
        your python interpreter from there.

